Workbook

Sheet delhi_business_cleaned
A1: area | B1: category_searched | C1: name | D1: address | E1: rating | F1: review_count | G1: website | H1: phone | I1: types | J1: checking_duplicates_to_remove | K1: Digital Presence | L1: rating_band | M1: Review_band | N1: Opportunity_Level
A2: Saket, Delhi | B2: mobile shops | C2: Vardaan Mobile | D2: J-1/9A, Gupta Colony, Khirki Extension, Malviya Nagar, New Delhi, Delhi 110017, India | E2: 5 | F2: 1017 | H2: 099903 24096 | I2: cell_phone_store, catering_service, food_delivery, store, finance, service, food, point_of_interest, establishment | J2: =IF(COUNTIFS($C$2:C2,C2,$D$2:D2,D2)=1,"Unique","Duplicate") -> Unique | K2: =IF(TRIM(G2)="","No Website", IF(OR( ISNUMBER(SEARCH("facebook",LOWER(G2))), ISNUMBER(SEARCH("instagram",LOWER(G2))), ISNUMBER(SEARCH("wa.me",LOWER(G2))), ISNUMBER(SEARCH("whatsapp",LOWER(G2))), ISNUMBER(SEARCH("youtube",LOWER(G2))), ISNUMBER(SEARCH("twitter",LOWER(G2))), ISNUMBER(SEARCH("x.com",LOWER(G2))), ISNUMBER(SEARCH("linkedin",LOWER(G2))), ISNUMBER(SEARCH("linktr.ee",LOWER(G2))), ISNUMBER(SEARCH("g.page",LOWER(G2))), ISNUMBER(SEARCH("maps.app.goo.gl",LOWER(G2))), ISNUMBER(SEARCH("goo.gl",LOWER(G2))) ), "Social Media", "Official Website")) -> No Website | L2: =IF(E2>=4.5,"Excellent", IF(E2>=4,"Good", IF(E2>=3,"Average","Poor"))) -> Excellent | M2: =IF(F2>=1000,"1000+ Reviews", IF(F2>=500,"500-999 Reviews", IF(F2>=100,"100-499 Reviews", "Below 100 Reviews"))) -> 1000+ Reviews | N2: =IF(K2="Official Website","Low Opportunity", IF(AND(K2="No Website",E2>=4.5,F2>=500),"Very High Opportunity", IF(AND(K2="No Website",E2>=4.5),"High Opportunity", IF(K2="Social Media","Medium Opportunity","Low Opportunity")))) -> Very High Opportunity
A3: Burari, Delhi | B3: restaurants | C3: Road Bench Cafe family restaurant | D3: 1st floor, near Medlife hospital and Bata showroom, Block D, Kamal Pur, Burari, Delhi, 110084, India | E3: 4.3 | F3: 337 | H3: 085859 57900 | I3: family_restaurant, restaurant, food, point_of_interest, establishment | J3: =IF(COUNTIFS($C$2:C3,C3,$D$2:D3,D3)=1,"Unique","Duplicate") -> Unique | K3: =IF(TRIM(G3)="","No Website", IF(OR( ISNUMBER(SEARCH("facebook",LOWER(G3))), ISNUMBER(SEARCH("instagram",LOWER(G3))), ISNUMBER(SEARCH("wa.me",LOWER(G3))), ISNUMBER(SEARCH("whatsapp",LOWER(G3))), ISNUMBER(SEARCH("youtube",LOWER(G3))), ISNUMBER(SEARCH("twitter",LOWER(G3))), ISNUMBER(SEARCH("x.com",LOWER(G3))), ISNUMBER(SEARCH("linkedin",LOWER(G3))), ISNUMBER(SEARCH("linktr.ee",LOWER(G3))), ISNUMBER(SEARCH("g.page",LOWER(G3))), ISNUMBER(SEARCH("maps.app.goo.gl",LOWER(G3))), ISNUMBER(SEARCH("goo.gl",LOWER(G3))) ), "Social Media", "Official Website")) -> No Website | L3: =IF(E3>=4.5,"Excellent", IF(E3>=4,"Good", IF(E3>=3,"Average","Poor"))) -> Good | M3: =IF(F3>=1000,"1000+ Reviews", IF(F3>=500,"500-999 Reviews", IF(F3>=100,"100-499 Reviews", "Below 100 Reviews"))) -> 100-499 Reviews | N3: =IF(K3="Official Website","Low Opportunity", IF(AND(K3="No Website",E3>=4.5,F3>=500),"Very High Opportunity", IF(AND(K3="No Website",E3>=4.5),"High Opportunity", IF(K3="Social Media","Medium Opportunity","Low Opportunity")))) -> Low Opportunity
A4: Burari, Delhi | B4: restaurants | C4: FOOD PITARRA | D4: Kh. No- 457/1, near Shalimar Palace, opposite Vindhya Shree Appartment, Indraprasth Colony, Burari, Delhi, 110084, India | E4: 4.2 | F4: 451 | G4: https://www.facebook.com/FoodPitarra/ | H4: 073037 70072 | I4: family_restaurant, restaurant, food, point_of_interest, establishment | J4: =IF(COUNTIFS($C$2:C4,C4,$D$2:D4,D4)=1,"Unique","Duplicate") -> Unique | K4: =IF(TRIM(G4)="","No Website", IF(OR( ISNUMBER(SEARCH("facebook",LOWER(G4))), ISNUMBER(SEARCH("instagram",LOWER(G4))), ISNUMBER(SEARCH("wa.me",LOWER(G4))), ISNUMBER(SEARCH("whatsapp",LOWER(G4))), ISNUMBER(SEARCH("youtube",LOWER(G4))), ISNUMBER(SEARCH("twitter",LOWER(G4))), ISNUMBER(SEARCH("x.com",LOWER(G4))), ISNUMBER(SEARCH("linkedin",LOWER(G4))), ISNUMBER(SEARCH("linktr.ee",LOWER(G4))), ISNUMBER(SEARCH("g.page",LOWER(G4))), ISNUMBER(SEARCH("maps.app.goo.gl",LOWER(G4))), ISNUMBER(SEARCH("goo.gl",LOWER(G4))) ), "Social Media", "Official Website")) -> Social Media | L4: =IF(E4>=4.5,"Excellent", IF(E4>=4,"Good", IF(E4>=3,"Average","Poor"))) -> Good | M4: =IF(F4>=1000,"1000+ Reviews", IF(F4>=500,"500-999 Reviews", IF(F4>=100,"100-499 Reviews", "Below 100 Reviews"))) -> 100-499 Reviews | N4: =IF(K4="Official Website","Low Opportunity", IF(AND(K4="No Website",E4>=4.5,F4>=500),"Very High Opportunity", IF(AND(K4="No Website",E4>=4.5),"High Opportunity", IF(K4="Social Media","Medium Opportunity","Low Opportunity")))) -> Medium Opportunity
A5: Burari, Delhi | B5: restaurants | C5: Mittal Sweets and Snacks | D5: Kh. No. 828, 100, Futta Main Road, Prem Nagar, Baba Colony, Burari, Delhi, 110084, India | E5: 4.6 | F5: 1276 | G5: https://www.mittalsweetandsnacks.com/ | H5: 098997 73223 | I5: restaurant, gift_shop, banquet_hall, fine_dining_restaurant, swimming_pool, bakery, event_venue, sports_activity_location, service, food_store, store, food, point_of_interest, establishment | J5: =IF(COUNTIFS($C$2:C5,C5,$D$2:D5,D5)=1,"Unique","Duplicate") -> Unique | K5: =IF(TRIM(G5)="","No Website", IF(OR( ISNUMBER(SEARCH("facebook",LOWER(G5))), ISNUMBER(SEARCH("instagram",LOWER(G5))), ISNUMBER(SEARCH("wa.me",LOWER(G5))), ISNUMBER(SEARCH("whatsapp",LOWER(G5))), ISNUMBER(SEARCH("youtube",LOWER(G5))), ISNUMBER(SEARCH("twitter",LOWER(G5))), ISNUMBER(SEARCH("x.com",LOWER(G5))), ISNUMBER(SEARCH("linkedin",LOWER(G5))), ISNUMBER(SEARCH("linktr.ee",LOWER(G5))), ISNUMBER(SEARCH("g.page",LOWER(G5))), ISNUMBER(SEARCH("maps.app.goo.gl",LOWER(G5))), ISNUMBER(SEARCH("goo.gl",LOWER(G5))) ), "Social Media", "Official Website")) -> Official Website | L5: =IF(E5>=4.5,"Excellent", IF(E5>=4,"Good", IF(E5>=3,"Average","Poor"))) -> Excellent | M5: =IF(F5>=1000,"1000+ Reviews", IF(F5>=500,"500-999 Reviews", IF(F5>=100,"100-499 Reviews", "Below 100 Reviews"))) -> 1000+ Reviews | N5: =IF(K5="Official Website","Low Opportunity", IF(AND(K5="No Website",E5>=4.5,F5>=500),"Very High Opportunity", IF(AND(K5="No Website",E5>=4.5),"High Opportunity", IF(K5="Social Media","Medium Opportunity","Low Opportunity")))) -> Low Opportunity
A6: Burari, Delhi | B6: restaurants | C6: Meet and Treat Cafe | D6: Street Number 4, near by Muthoot finance, A-2 Block, Virendar Nagar, Block B, West Sant Nagar, Burari, Delhi, 110084, India | E6: 4.6 | F6: 504 | G6: https://meet-and-treat-cafe.grexa.site/ | H6: 090131 61184 | I6: restaurant, food, point_of_interest, establishment | J6: =IF(COUNTIFS($C$2:C6,C6,$D$2:D6,D6)=1,"Unique","Duplicate") -> Unique | K6: =IF(TRIM(G6)="","No Website", IF(OR( ISNUMBER(SEARCH("facebook",LOWER(G6))), ISNUMBER(SEARCH("instagram",LOWER(G6))), ISNUMBER(SEARCH("wa.me",LOWER(G6))), ISNUMBER(SEARCH("whatsapp",LOWER(G6))), ISNUMBER(SEARCH("youtube",LOWER(G6))), ISNUMBER(SEARCH("twitter",LOWER(G6))), ISNUMBER(SEARCH("x.com",LOWER(G6))), ISNUMBER(SEARCH("linkedin",LOWER(G6))), ISNUMBER(SEARCH("linktr.ee",LOWER(G6))), ISNUMBER(SEARCH("g.page",LOWER(G6))), ISNUMBER(SEARCH("maps.app.goo.gl",LOWER(G6))), ISNUMBER(SEARCH("goo.gl",LOWER(G6))) ), "Social Media", "Official Website")) -> Official Website | L6: =IF(E6>=4.5,"Excellent", IF(E6>=4,"Good", IF(E6>=3,"Average","Poor"))) -> Excellent | M6: =IF(F6>=1000,"1000+ Reviews", IF(F6>=500,"500-999 Reviews", IF(F6>=100,"100-499 Reviews", "Below 100 Reviews"))) -> 500-999 Reviews | N6: =IF(K6="Official Website","Low Opportunity", IF(AND(K6="No Website",E6>=4.5,F6>=500),"Very High Opportunity", IF(AND(K6="No Website",E6>=4.5),"High Opportunity", IF(K6="Social Media","Medium Opportunity","Low Opportunity")))) -> Low Opportunity
A7: Connaught Place, New Delhi | B7: clothing stores | C7: Fashion Craft | D7: Shop no 74, Municipal Market, opp. Pizza Hut, Janpath, Connaught Place, New Delhi, Delhi 110001, India | E7: 5 | F7: 987 | H7: 084474 99885 | I7: clothing_store, wholesaler, store, manufacturer, point_of_interest, establishment | J7: =IF(COUNTIFS($C$2:C7,C7,$D$2:D7,D7)=1,"Unique","Duplicate") -> Unique | K7: =IF(TRIM(G7)="","No Website", IF(OR( ISNUMBER(SEARCH("facebook",LOWER(G7))), ISNUMBER(SEARCH("instagram",LOWER(G7))), ISNUMBER(SEARCH("wa.me",LOWER(G7))), ISNUMBER(SEARCH("whatsapp",LOWER(G7))), ISNUMBER(SEARCH("youtube",LOWER(G7))), ISNUMBER(SEARCH("twitter",LOWER(G7))), ISNUMBER(SEARCH("x.com",LOWER(G7))), ISNUMBER(SEARCH("linkedin",LOWER(G7))), ISNUMBER(SEARCH("linktr.ee",LOWER(G7))), ISNUMBER(SEARCH("g.page",LOWER(G7))), ISNUMBER(SEARCH("maps.app.goo.gl",LOWER(G7))), ISNUMBER(SEARCH("goo.gl",LOWER(G7))) ), "Social Media", "Official Website")) -> No Website | L7: =IF(E7>=4.5,"Excellent", IF(E7>=4,"Good", IF(E7>=3,"Average","Poor"))) -> Excellent | M7: =IF(F7>=1000,"1000+ Reviews", IF(F7>=500,"500-999 Reviews", IF(F7>=100,"100-499 Reviews", "Below 100 Reviews"))) -> 500-999 Reviews | N7: =IF(K7="Official Website","Low Opportunity", IF(AND(K7="No Website",E7>=4.5,F7>=500),"Very High Opportunity", IF(AND(K7="No Website",E7>=4.5),"High Opportunity", IF(K7="Social Media","Medium Opportunity","Low Opportunity")))) -> Very High Opportunity
A8: Burari, Delhi | B8: restaurants | C8: Zaiyka Punjab | D8: Labour chowk, Sant Nagar Marg, Parvatiya Anchal, Block B, Sant Nagar, Burari, New Delhi, Delhi, 110084, India | E8: 3.9 | F8: 1454 | G8: https://zaikarestaurant.org/ | H8: 099901 07009 | I8: pakistani_restaurant, north_indian_restaurant, indian_restaurant, restaurant, food, point_of_interest, establishment | J8: =IF(COUNTIFS($C$2:C8,C8,$D$2:D8,D8)=1,"Unique","Duplicate") -> Unique | K8: =IF(TRIM(G8)="","No Website", IF(OR( ISNUMBER(SEARCH("facebook",LOWER(G8))), ISNUMBER(SEARCH("instagram",LOWER(G8))), ISNUMBER(SEARCH("wa.me",LOWER(G8))), ISNUMBER(SEARCH("whatsapp",LOWER(G8))), ISNUMBER(SEARCH("youtube",LOWER(G8))), ISNUMBER(SEARCH("twitter",LOWER(G8))), ISNUMBER(SEARCH("x.com",LOWER(G8))), ISNUMBER(SEARCH("linkedin",LOWER(G8))), ISNUMBER(SEARCH("linktr.ee",LOWER(G8))), ISNUMBER(SEARCH("g.page",LOWER(G8))), ISNUMBER(SEARCH("maps.app.goo.gl",LOWER(G8))), ISNUMBER(SEARCH("goo.gl",LOWER(G8))) ), "Social Media", "Official Website")) -> Official Website | L8: =IF(E8>=4.5,"Excellent", IF(E8>=4,"Good", IF(E8>=3,"Average","Poor"))) -> Average | M8: =IF(F8>=1000,"1000+ Reviews", IF(F8>=500,"500-999 Reviews", IF(F8>=100,"100-499 Reviews", "Below 100 Reviews"))) -> 1000+ Reviews | N8: =IF(K8="Official Website","Low Opportunity", IF(AND(K8="No Website",E8>=4.5,F8>=500),"Very High Opportunity", IF(AND(K8="No Website",E8>=4.5),"High Opportunity", IF(K8="Social Media","Medium Opportunity","Low Opportunity")))) -> Low Opportunity
A9: Burari, Delhi | B9: restaurants | C9: Utsav Dhaba | D9: Kh.No. 47/1 ,Gali No. 01 , Kaushik Enclave Main, 100ft, Road, opposite Burari Government hospital, Block D, Indraprasth Colony, Burari, Delhi, 110084, India | E9: 4.4 | F9: 193 | H9: 088088 80900 | I9: indian_restaurant, restaurant, food, point_of_interest, establishment | J9: =IF(COUNTIFS($C$2:C9,C9,$D$2:D9,D9)=1,"Unique","Duplicate") -> Unique | K9: =IF(TRIM(G9)="","No Website", IF(OR( ISNUMBER(SEARCH("facebook",LOWER(G9))), ISNUMBER(SEARCH("instagram",LOWER(G9))), ISNUMBER(SEARCH("wa.me",LOWER(G9))), ISNUMBER(SEARCH("whatsapp",LOWER(G9))), ISNUMBER(SEARCH("youtube",LOWER(G9))), ISNUMBER(SEARCH("twitter",LOWER(G9))), ISNUMBER(SEARCH("x.com",LOWER(G9))), ISNUMBER(SEARCH("linkedin",LOWER(G9))), ISNUMBER(SEARCH("linktr.ee",LOWER(G9))), ISNUMBER(SEARCH("g.page",LOWER(G9))), ISNUMBER(SEARCH("maps.app.goo.gl",LOWER(G9))), ISNUMBER(SEARCH("goo.gl",LOWER(G9))) ), "Social Media", "Official Website")) -> No Website | L9: =IF(E9>=4.5,"Excellent", IF(E9>=4,"Good", IF(E9>=3,"Average","Poor"))) -> Good | M9: =IF(F9>=1000,"1000+ Reviews", IF(F9>=500,"500-999 Reviews", IF(F9>=100,"100-499 Reviews", "Below 100 Reviews"))) -> 100-499 Reviews | N9: =IF(K9="Official Website","Low Opportunity", IF(AND(K9="No Website",E9>=4.5,F9>=500),"Very High Opportunity", IF(AND(K9="No Website",E9>=4.5),"High Opportunity", IF(K9="Social Media","Medium Opportunity","Low Opportunity")))) -> Low Opportunity
A10: Burari, Delhi | B10: restaurants | C10: Roms Pizza Burari | D10: 108, 100 Feet Rd, Virendar Nagar, Block B, Sant Nagar, Burari, Delhi, 110084, India | E10: 4.8 | F10: 1520 | G10: https://romspizzaburari.edgeone.app/ | H10: 097187 07077 | I10: pizza_restaurant, restaurant, food, point_of_interest, establishment | J10: =IF(COUNTIFS($C$2:C10,C10,$D$2:D10,D10)=1,"Unique","Duplicate") -> Unique | K10: =IF(TRIM(G10)="","No Website", IF(OR( ISNUMBER(SEARCH("facebook",LOWER(G10))), ISNUMBER(SEARCH("instagram",LOWER(G10))), ISNUMBER(SEARCH("wa.me",LOWER(G10))), ISNUMBER(SEARCH("whatsapp",LOWER(G10))), ISNUMBER(SEARCH("youtube",LOWER(G10))), ISNUMBER(SEARCH("twitter",LOWER(G10))), ISNUMBER(SEARCH("x.com",LOWER(G10))), ISNUMBER(SEARCH("linkedin",LOWER(G10))), ISNUMBER(SEARCH("linktr.ee",LOWER(G10))), ISNUMBER(SEARCH("g.page",LOWER(G10))), ISNUMBER(SEARCH("maps.app.goo.gl",LOWER(G10))), ISNUMBER(SEARCH("goo.gl",LOWER(G10))) ), "Social Media", "Official Website")) -> Official Website | L10: =IF(E10>=4.5,"Excellent", IF(E10>=4,"Good", IF(E10>=3,"Average","Poor"))) -> Excellent | M10: =IF(F10>=1000,"1000+ Reviews", IF(F10>=500,"500-999 Reviews", IF(F10>=100,"100-499 Reviews", "Below 100 Reviews"))) -> 1000+ Reviews | N10: =IF(K10="Official Website","Low Opportunity", IF(AND(K10="No Website",E10>=4.5,F10>=500),"Very High Opportunity", IF(AND(K10="No Website",E10>=4.5),"High Opportunity", IF(K10="Social Media","Medium Opportunity","Low Opportunity")))) -> Low Opportunity
A11: Burari, Delhi | B11: restaurants | C11: Royal Delhi Family Restaurant | D11: Shop No 5 Ground Floor, Main 100, Foota Rd, opp. Raj Mandir, Vijay Colony, Block B, West Sant Nagar, Burari, Delhi, 110084, India | E11: 4.8 | F11: 21 | G11: https://g.page/r/CfFeR9pYUVdqEBM/review | H11: 088008 75466 | I11: restaurant, food, point_of_interest, establishment | J11: =IF(COUNTIFS($C$2:C11,C11,$D$2:D11,D11)=1,"Unique","Duplicate") -> Unique | K11: =IF(TRIM(G11)="","No Website", IF(OR( ISNUMBER(SEARCH("facebook",LOWER(G11))), ISNUMBER(SEARCH("instagram",LOWER(G11))), ISNUMBER(SEARCH("wa.me",LOWER(G11))), ISNUMBER(SEARCH("whatsapp",LOWER(G11))), ISNUMBER(SEARCH("youtube",LOWER(G11))), ISNUMBER(SEARCH("twitter",LOWER(G11))), ISNUMBER(SEARCH("x.com",LOWER(G11))), ISNUMBER(SEARCH("linkedin",LOWER(G11))), ISNUMBER(SEARCH("linktr.ee",LOWER(G11))), ISNUMBER(SEARCH("g.page",LOWER(G11))), ISNUMBER(SEARCH("maps.app.goo.gl",LOWER(G11))), ISNUMBER(SEARCH("goo.gl",LOWER(G11))) ), "Social Media", "Official Website")) -> Social Media | L11: =IF(E11>=4.5,"Excellent", IF(E11>=4,"Good", IF(E11>=3,"Average","Poor"))) -> Excellent | M11: =IF(F11>=1000,"1000+ Reviews", IF(F11>=500,"500-999 Reviews", IF(F11>=100,"100-499 Reviews", "Below 100 Reviews"))) -> Below 100 Reviews | N11: =IF(K11="Official Website","Low Opportunity", IF(AND(K11="No Website",E11>=4.5,F11>=500),"Very High Opportunity", IF(AND(K11="No Website",E11>=4.5),"High Opportunity", IF(K11="Social Media","Medium Opportunity","Low Opportunity")))) -> Medium Opportunity
A12: Burari, Delhi | B12: restaurants | C12: MISHRI LAL JI KI RASOI BURARI | D12: Parvati Anchal, 870/3, Gali No. 2, B Block, Shami Park, Sant Nagar, Burari, Delhi, 110084, India | E12: 4.9 | F12: 43 | G12: https://link.zomato.com/xqzv/rshare?id=11117118730563605 | H12: 070119 39626 | I12: restaurant, food, point_of_interest, establishment | J12: =IF(COUNTIFS($C$2:C12,C12,$D$2:D12,D12)=1,"Unique","Duplicate") -> Unique | K12: =IF(TRIM(G12)="","No Website", IF(OR( ISNUMBER(SEARCH("facebook",LOWER(G12))), ISNUMBER(SEARCH("instagram",LOWER(G12))), ISNUMBER(SEARCH("wa.me",LOWER(G12))), ISNUMBER(SEARCH("whatsapp",LOWER(G12))), ISNUMBER(SEARCH("youtube",LOWER(G12))), ISNUMBER(SEARCH("twitter",LOWER(G12))), ISNUMBER(SEARCH("x.com",LOWER(G12))), ISNUMBER(SEARCH("linkedin",LOWER(G12))), ISNUMBER(SEARCH("linktr.ee",LOWER(G12))), ISNUMBER(SEARCH("g.page",LOWER(G12))), ISNUMBER(SEARCH("maps.app.goo.gl",LOWER(G12))), ISNUMBER(SEARCH("goo.gl",LOWER(G12))) ), "Social Media", "Official Website")) -> Official Website | L12: =IF(E12>=4.5,"Excellent", IF(E12>=4,"Good", IF(E12>=3,"Average","Poor"))) -> Excellent | M12: =IF(F12>=1000,"1000+ Reviews", IF(F12>=500,"500-999 Reviews", IF(F12>=100,"100-499 Reviews", "Below 100 Reviews"))) -> Below 100 Reviews | N12: =IF(K12="Official Website","Low Opportunity", IF(AND(K12="No Website",E12>=4.5,F12>=500),"Very High Opportunity", IF(AND(K12="No Website",E12>=4.5),"High Opportunity", IF(K12="Social Media","Medium Opportunity","Low Opportunity")))) -> Low Opportunity
A13: Burari, Delhi | B13: restaurants | C13: GARHWAL PUNJABI TADKA | D13: Labour Chowk, 100 Feet Rd, Block B, Sant Nagar, Burari, Delhi, 110084, India | E13: 3.7 | F13: 268 | G13: https://garhwalpunjabitadka.co.in/ | H13: 070425 10609 | I13: pakistani_restaurant, north_indian_restaurant, indian_restaurant, restaurant, food, point_of_interest, establishment | J13: =IF(COUNTIFS($C$2:C13,C13,$D$2:D13,D13)=1,"Unique","Duplicate") -> Unique | K13: =IF(TRIM(G13)="","No Website", IF(OR( ISNUMBER(SEARCH("facebook",LOWER(G13))), ISNUMBER(SEARCH("instagram",LOWER(G13))), ISNUMBER(SEARCH("wa.me",LOWER(G13))), ISNUMBER(SEARCH("whatsapp",LOWER(G13))), ISNUMBER(SEARCH("youtube",LOWER(G13))), ISNUMBER(SEARCH("twitter",LOWER(G13))), ISNUMBER(SEARCH("x.com",LOWER(G13))), ISNUMBER(SEARCH("linkedin",LOWER(G13))), ISNUMBER(SEARCH("linktr.ee",LOWER(G13))), ISNUMBER(SEARCH("g.page",LOWER(G13))), ISNUMBER(SEARCH("maps.app.goo.gl",LOWER(G13))), ISNUMBER(SEARCH("goo.gl",LOWER(G13))) ), "Social Media", "Official Website")) -> Official Website | L13: =IF(E13>=4.5,"Excellent", IF(E13>=4,"Good", IF(E13>=3,"Average","Poor"))) -> Average | M13: =IF(F13>=1000,"1000+ Reviews", IF(F13>=500,"500-999 Reviews", IF(F13>=100,"100-499 Reviews", "Below 100 Reviews"))) -> 100-499 Reviews | N13: =IF(K13="Official Website","Low Opportunity", IF(AND(K13="No Website",E13>=4.5,F13>=500),"Very High Opportunity", IF(AND(K13="No Website",E13>=4.5),"High Opportunity", IF(K13="Social Media","Medium Opportunity","Low Opportunity")))) -> Low Opportunity
A14: Burari, Delhi | B14: restaurants | C14: Tasty bite restaurant | D14: Maurya Enclave, Upakar Colony, Burari, New delhi, Delhi, 110084, India | E14: 3.7 | F14: 1127 | H14: 075308 08188 | I14: restaurant, fast_food_restaurant, food, point_of_interest, establishment | J14: =IF(COUNTIFS($C$2:C14,C14,$D$2:D14,D14)=1,"Unique","Duplicate") -> Unique | K14: =IF(TRIM(G14)="","No Website", IF(OR( ISNUMBER(SEARCH("facebook",LOWER(G14))), ISNUMBER(SEARCH("instagram",LOWER(G14))), ISNUMBER(SEARCH("wa.me",LOWER(G14))), ISNUMBER(SEARCH("whatsapp",LOWER(G14))), ISNUMBER(SEARCH("youtube",LOWER(G14))), ISNUMBER(SEARCH("twitter",LOWER(G14))), ISNUMBER(SEARCH("x.com",LOWER(G14))), ISNUMBER(SEARCH("linkedin",LOWER(G14))), ISNUMBER(SEARCH("linktr.ee",LOWER(G14))), ISNUMBER(SEARCH("g.page",LOWER(G14))), ISNUMBER(SEARCH("maps.app.goo.gl",LOWER(G14))), ISNUMBER(SEARCH("goo.gl",LOWER(G14))) ), "Social Media", "Official Website")) -> No Website | L14: =IF(E14>=4.5,"Excellent", IF(E14>=4,"Good", IF(E14>=3,"Average","Poor"))) -> Average | M14: =IF(F14>=1000,"1000+ Reviews", IF(F14>=500,"500-999 Reviews", IF(F14>=100,"100-499 Reviews", "Below 100 Reviews"))) -> 1000+ Reviews | N14: =IF(K14="Official Website","Low Opportunity", IF(AND(K14="No Website",E14>=4.5,F14>=500),"Very High Opportunity", IF(AND(K14="No Website",E14>=4.5),"High Opportunity", IF(K14="Social Media","Medium Opportunity","Low Opportunity")))) -> Low Opportunity
A15: Pitampura, Delhi | B15: mobile shops | C15: GUPTA MOBILE TELECOM | D15: I-262, Block I, Shakurpur Colony, Pitampura, Delhi, 110034, India | E15: 5 | F15: 814 | H15: 078383 30007 | I15: cell_phone_store, electronics_store, store, service, point_of_interest, establishment | J15: =IF(COUNTIFS($C$2:C15,C15,$D$2:D15,D15)=1,"Unique","Duplicate") -> Unique | K15: =IF(TRIM(G15)="","No Website", IF(OR( ISNUMBER(SEARCH("facebook",LOWER(G15))), ISNUMBER(SEARCH("instagram",LOWER(G15))), ISNUMBER(SEARCH("wa.me",LOWER(G15))), ISNUMBER(SEARCH("whatsapp",LOWER(G15))), ISNUMBER(SEARCH("youtube",LOWER(G15))), ISNUMBER(SEARCH("twitter",LOWER(G15))), ISNUMBER(SEARCH("x.com",LOWER(G15))), ISNUMBER(SEARCH("linkedin",LOWER(G15))), ISNUMBER(SEARCH("linktr.ee",LOWER(G15))), ISNUMBER(SEARCH("g.page",LOWER(G15))), ISNUMBER(SEARCH("maps.app.goo.gl",LOWER(G15))), ISNUMBER(SEARCH("goo.gl",LOWER(G15))) ), "Social Media", "Official Website")) -> No Website | L15: =IF(E15>=4.5,"Excellent", IF(E15>=4,"Good", IF(E15>=3,"Average","Poor"))) -> Excellent | M15: =IF(F15>=1000,"1000+ Reviews", IF(F15>=500,"500-999 Reviews", IF(F15>=100,"100-499 Reviews", "Below 100 Reviews"))) -> 500-999 Reviews | N15: =IF(K15="Official Website","Low Opportunity", IF(AND(K15="No Website",E15>=4.5,F15>=500),"Very High Opportunity", IF(AND(K15="No Website",E15>=4.5),"High Opportunity", IF(K15="Social Media","Medium Opportunity","Low Opportunity")))) -> Very High Opportunity
A16: Burari, Delhi | B16: restaurants | C16: Delhi Grillz restaurant | D16: A-9, Extension Colony, Burari, Delhi, 110084, India | E16: 4 | F16: 530 | H16: 098115 11612 | I16: north_indian_restaurant, indian_restaurant, restaurant, food, point_of_interest, establishment | J16: =IF(COUNTIFS($C$2:C16,C16,$D$2:D16,D16)=1,"Unique","Duplicate") -> Unique | K16: =IF(TRIM(G16)="","No Website", IF(OR( ISNUMBER(SEARCH("facebook",LOWER(G16))), ISNUMBER(SEARCH("instagram",LOWER(G16))), ISNUMBER(SEARCH("wa.me",LOWER(G16))), ISNUMBER(SEARCH("whatsapp",LOWER(G16))), ISNUMBER(SEARCH("youtube",LOWER(G16))), ISNUMBER(SEARCH("twitter",LOWER(G16))), ISNUMBER(SEARCH("x.com",LOWER(G16))), ISNUMBER(SEARCH("linkedin",LOWER(G16))), ISNUMBER(SEARCH("linktr.ee",LOWER(G16))), ISNUMBER(SEARCH("g.page",LOWER(G16))), ISNUMBER(SEARCH("maps.app.goo.gl",LOWER(G16))), ISNUMBER(SEARCH("goo.gl",LOWER(G16))) ), "Social Media", "Official Website")) -> No Website | L16: =IF(E16>=4.5,"Excellent", IF(E16>=4,"Good", IF(E16>=3,"Average","Poor"))) -> Good | M16: =IF(F16>=1000,"1000+ Reviews", IF(F16>=500,"500-999 Reviews", IF(F16>=100,"100-499 Reviews", "Below 100 Reviews"))) -> 500-999 Reviews | N16: =IF(K16="Official Website","Low Opportunity", IF(AND(K16="No Website",E16>=4.5,F16>=500),"Very High Opportunity", IF(AND(K16="No Website",E16>=4.5),"High Opportunity", IF(K16="Social Media","Medium Opportunity","Low Opportunity")))) -> Low Opportunity
A17: Kamla Nagar, Delhi | B17: clothing stores | C17: Libas | D17: Shop No. 42, 43, Jawahar Nagar - Malka Ganj Rd, Block UB, Jawahar Nagar, Kamla Nagar, New Delhi, Delhi, 110007, India | E17: 5 | F17: 782 | H17: 099108 53530 | I17: clothing_store, store, point_of_interest, establishment | J17: =IF(COUNTIFS($C$2:C17,C17,$D$2:D17,D17)=1,"Unique","Duplicate") -> Unique | K17: =IF(TRIM(G17)="","No Website", IF(OR( ISNUMBER(SEARCH("facebook",LOWER(G17))), ISNUMBER(SEARCH("instagram",LOWER(G17))), ISNUMBER(SEARCH("wa.me",LOWER(G17))), ISNUMBER(SEARCH("whatsapp",LOWER(G17))), ISNUMBER(SEARCH("youtube",LOWER(G17))), ISNUMBER(SEARCH("twitter",LOWER(G17))), ISNUMBER(SEARCH("x.com",LOWER(G17))), ISNUMBER(SEARCH("linkedin",LOWER(G17))), ISNUMBER(SEARCH("linktr.ee",LOWER(G17))), ISNUMBER(SEARCH("g.page",LOWER(G17))), ISNUMBER(SEARCH("maps.app.goo.gl",LOWER(G17))), ISNUMBER(SEARCH("goo.gl",LOWER(G17))) ), "Social Media", "Official Website")) -> No Website | L17: =IF(E17>=4.5,"Excellent", IF(E17>=4,"Good", IF(E17>=3,"Average","Poor"))) -> Excellent | M17: =IF(F17>=1000,"1000+ Reviews", IF(F17>=500,"500-999 Reviews", IF(F17>=100,"100-499 Reviews", "Below 100 Reviews"))) -> 500-999 Reviews | N17: =IF(K17="Official Website","Low Opportunity", IF(AND(K17="No Website",E17>=4.5,F17>=500),"Very High Opportunity", IF(AND(K17="No Website",E17>=4.5),"High Opportunity", IF(K17="Social Media","Medium Opportunity","Low Opportunity")))) -> Very High Opportunity
A18: Burari, Delhi | B18: restaurants | C18: WAH JI WAH restaurant Burari | D18: Main 100, Kh.no.19/26, Foota Rd, b block, Kaushik Enclave, Shankarpura, Burari, Delhi, 110084, India | E18: 3.7 | F18: 49 | H18: 070110 46566 | I18: restaurant, food, point_of_interest, establishment | J18: =IF(COUNTIFS($C$2:C18,C18,$D$2:D18,D18)=1,"Unique","Duplicate") -> Unique | K18: =IF(TRIM(G18)="","No Website", IF(OR( ISNUMBER(SEARCH("facebook",LOWER(G18))), ISNUMBER(SEARCH("instagram",LOWER(G18))), ISNUMBER(SEARCH("wa.me",LOWER(G18))), ISNUMBER(SEARCH("whatsapp",LOWER(G18))), ISNUMBER(SEARCH("youtube",LOWER(G18))), ISNUMBER(SEARCH("twitter",LOWER(G18))), ISNUMBER(SEARCH("x.com",LOWER(G18))), ISNUMBER(SEARCH("linkedin",LOWER(G18))), ISNUMBER(SEARCH("linktr.ee",LOWER(G18))), ISNUMBER(SEARCH("g.page",LOWER(G18))), ISNUMBER(SEARCH("maps.app.goo.gl",LOWER(G18))), ISNUMBER(SEARCH("goo.gl",LOWER(G18))) ), "Social Media", "Official Website")) -> No Website | L18: =IF(E18>=4.5,"Excellent", IF(E18>=4,"Good", IF(E18>=3,"Average","Poor"))) -> Average | M18: =IF(F18>=1000,"1000+ Reviews", IF(F18>=500,"500-999 Reviews", IF(F18>=100,"100-499 Reviews", "Below 100 Reviews"))) -> Below 100 Reviews | N18: =IF(K18="Official Website","Low Opportunity", IF(AND(K18="No Website",E18>=4.5,F18>=500),"Very High Opportunity", IF(AND(K18="No Website",E18>=4.5),"High Opportunity", IF(K18="Social Media","Medium Opportunity","Low Opportunity")))) -> Low Opportunity
A19: Burari, Delhi | B19: restaurants | C19: JAI SHREE RESTAURANT BANQUET HOTEL | D19: Nathupura Rd, Saroop Vihar, A Block, Indraprasth Colony, Burari, Delhi, 110084, India | E19: 4.1 | F19: 1129 | H19: 073037 20692 | I19: vegetarian_restaurant, banquet_hall, north_indian_restaurant, south_indian_restaurant, hotel, indian_restaurant, chinese_restaurant, event_venue, lodging, restaurant, food, point_of_interest, establishment | J19: =IF(COUNTIFS($C$2:C19,C19,$D$2:D19,D19)=1,"Unique","Duplicate") -> Unique | K19: =IF(TRIM(G19)="","No Website", IF(OR( ISNUMBER(SEARCH("facebook",LOWER(G19))), ISNUMBER(SEARCH("instagram",LOWER(G19))), ISNUMBER(SEARCH("wa.me",LOWER(G19))), ISNUMBER(SEARCH("whatsapp",LOWER(G19))), ISNUMBER(SEARCH("youtube",LOWER(G19))), ISNUMBER(SEARCH("twitter",LOWER(G19))), ISNUMBER(SEARCH("x.com",LOWER(G19))), ISNUMBER(SEARCH("linkedin",LOWER(G19))), ISNUMBER(SEARCH("linktr.ee",LOWER(G19))), ISNUMBER(SEARCH("g.page",LOWER(G19))), ISNUMBER(SEARCH("maps.app.goo.gl",LOWER(G19))), ISNUMBER(SEARCH("goo.gl",LOWER(G19))) ), "Social Media", "Official Website")) -> No Website | L19: =IF(E19>=4.5,"Excellent", IF(E19>=4,"Good", IF(E19>=3,"Average","Poor"))) -> Good | M19: =IF(F19>=1000,"1000+ Reviews", IF(F19>=500,"500-999 Reviews", IF(F19>=100,"100-499 Reviews", "Below 100 Reviews"))) -> 1000+ Reviews | N19: =IF(K19="Official Website","Low Opportunity", IF(AND(K19="No Website",E19>=4.5,F19>=500),"Very High Opportunity", IF(AND(K19="No Website",E19>=4.5),"High Opportunity", IF(K19="Social Media","Medium Opportunity","Low Opportunity")))) -> Low Opportunity
A20: Burari, Delhi | B20: restaurants | C20: Burari 84, The Authentic Indian Kitchen | D20: Shop No 4, Ground Floor, Vinayak Apartments, Vijay Colony, Block B, Sant Nagar, Burari, New Delhi, Delhi, 110084, India | E20: 3.2 | F20: 52 | H20: 085880 03009 | I20: pizza_restaurant, restaurant, food, point_of_interest, establishment | J20: =IF(COUNTIFS($C$2:C20,C20,$D$2:D20,D20)=1,"Unique","Duplicate") -> Unique | K20: =IF(TRIM(G20)="","No Website", IF(OR( ISNUMBER(SEARCH("facebook",LOWER(G20))), ISNUMBER(SEARCH("instagram",LOWER(G20))), ISNUMBER(SEARCH("wa.me",LOWER(G20))), ISNUMBER(SEARCH("whatsapp",LOWER(G20))), ISNUMBER(SEARCH("youtube",LOWER(G20))), ISNUMBER(SEARCH("twitter",LOWER(G20))), ISNUMBER(SEARCH("x.com",LOWER(G20))), ISNUMBER(SEARCH("linkedin",LOWER(G20))), ISNUMBER(SEARCH("linktr.ee",LOWER(G20))), ISNUMBER(SEARCH("g.page",LOWER(G20))), ISNUMBER(SEARCH("maps.app.goo.gl",LOWER(G20))), ISNUMBER(SEARCH("goo.gl",LOWER(G20))) ), "Social Media", "Official Website")) -> No Website | L20: =IF(E20>=4.5,"Excellent", IF(E20>=4,"Good", IF(E20>=3,"Average","Poor"))) -> Average | M20: =IF(F20>=1000,"1000+ Reviews", IF(F20>=500,"500-999 Reviews", IF(F20>=100,"100-499 Reviews", "Below 100 Reviews"))) -> Below 100 Reviews | N20: =IF(K20="Official Website","Low Opportunity", IF(AND(K20="No Website",E20>=4.5,F20>=500),"Very High Opportunity", IF(AND(K20="No Website",E20>=4.5),"High Opportunity", IF(K20="Social Media","Medium Opportunity","Low Opportunity")))) -> Low Opportunity
A21: Mayur Vihar, Delhi | B21: bakeries | C21: Bakingham - The Bake Town | D21: Shop No. 18 & 25, DDA LSC, Block A, Acharya Niketan, Mayur Vihar, Delhi, 110091, India | E21: 5 | F21: 679 | H21: 093157 86908 | I21: bakery, food_store, store, food, point_of_interest, establishment | J21: =IF(COUNTIFS($C$2:C21,C21,$D$2:D21,D21)=1,"Unique","Duplicate") -> Unique | K21: =IF(TRIM(G21)="","No Website", IF(OR( ISNUMBER(SEARCH("facebook",LOWER(G21))), ISNUMBER(SEARCH("instagram",LOWER(G21))), ISNUMBER(SEARCH("wa.me",LOWER(G21))), ISNUMBER(SEARCH("whatsapp",LOWER(G21))), ISNUMBER(SEARCH("youtube",LOWER(G21))), ISNUMBER(SEARCH("twitter",LOWER(G21))), ISNUMBER(SEARCH("x.com",LOWER(G21))), ISNUMBER(SEARCH("linkedin",LOWER(G21))), ISNUMBER(SEARCH("linktr.ee",LOWER(G21))), ISNUMBER(SEARCH("g.page",LOWER(G21))), ISNUMBER(SEARCH("maps.app.goo.gl",LOWER(G21))), ISNUMBER(SEARCH("goo.gl",LOWER(G21))) ), "Social Media", "Official Website")) -> No Website | L21: =IF(E21>=4.5,"Excellent", IF(E21>=4,"Good", IF(E21>=3,"Average","Poor"))) -> Excellent | M21: =IF(F21>=1000,"1000+ Reviews", IF(F21>=500,"500-999 Reviews", IF(F21>=100,"100-499 Reviews", "Below 100 Reviews"))) -> 500-999 Reviews | N21: =IF(K21="Official Website","Low Opportunity", IF(AND(K21="No Website",E21>=4.5,F21>=500),"Very High Opportunity", IF(AND(K21="No Website",E21>=4.5),"High Opportunity", IF(K21="Social Media","Medium Opportunity","Low Opportunity")))) -> Very High Opportunity
A22: Burari, Delhi | B22: cafes | C22: Tealogy Cafe Burari | D22: Khasra 137/23/2/2 Shop number 1, gate no 2, 100 Feet Rd, behind Rani public school, A-2 Block, Block B, Sant Nagar, Burari, New Delhi, Delhi, 110084, India | E22: 4.8 | F22: 641 | G22: https://tealogy.in/city/tea-cafe-franchise-burari | H22: 098211 94456 | I22: cafe, food, point_of_interest, establishment | J22: =IF(COUNTIFS($C$2:C22,C22,$D$2:D22,D22)=1,"Unique","Duplicate") -> Unique | K22: =IF(TRIM(G22)="","No Website", IF(OR( ISNUMBER(SEARCH("facebook",LOWER(G22))), ISNUMBER(SEARCH("instagram",LOWER(G22))), ISNUMBER(SEARCH("wa.me",LOWER(G22))), ISNUMBER(SEARCH("whatsapp",LOWER(G22))), ISNUMBER(SEARCH("youtube",LOWER(G22))), ISNUMBER(SEARCH("twitter",LOWER(G22))), ISNUMBER(SEARCH("x.com",LOWER(G22))), ISNUMBER(SEARCH("linkedin",LOWER(G22))), ISNUMBER(SEARCH("linktr.ee",LOWER(G22))), ISNUMBER(SEARCH("g.page",LOWER(G22))), ISNUMBER(SEARCH("maps.app.goo.gl",LOWER(G22))), ISNUMBER(SEARCH("goo.gl",LOWER(G22))) ), "Social Media", "Official Website")) -> Official Website | L22: =IF(E22>=4.5,"Excellent", IF(E22>=4,"Good", IF(E22>=3,"Average","Poor"))) -> Excellent | M22: =IF(F22>=1000,"1000+ Reviews", IF(F22>=500,"500-999 Reviews", IF(F22>=100,"100-499 Reviews", "Below 100 Reviews"))) -> 500-999 Reviews | N22: =IF(K22="Official Website","Low Opportunity", IF(AND(K22="No Website",E22>=4.5,F22>=500),"Very High Opportunity", IF(AND(K22="No Website",E22>=4.5),"High Opportunity", IF(K22="Social Media","Medium Opportunity","Low Opportunity")))) -> Low Opportunity
A23: Kalkaji, Delhi | B23: jewellery shops | C23: GURU NANAK GEMS & JEWELS | D23: 339, Gali Number 4, Govind Puri, Kalkaji, New Delhi, Delhi 110019, India | E23: 5 | F23: 654 | H23: 078385 45144 | I23: jewelry_store, store, point_of_interest, establishment | J23: =IF(COUNTIFS($C$2:C23,C23,$D$2:D23,D23)=1,"Unique","Duplicate") -> Unique | K23: =IF(TRIM(G23)="","No Website", IF(OR( ISNUMBER(SEARCH("facebook",LOWER(G23))), ISNUMBER(SEARCH("instagram",LOWER(G23))), ISNUMBER(SEARCH("wa.me",LOWER(G23))), ISNUMBER(SEARCH("whatsapp",LOWER(G23))), ISNUMBER(SEARCH("youtube",LOWER(G23))), ISNUMBER(SEARCH("twitter",LOWER(G23))), ISNUMBER(SEARCH("x.com",LOWER(G23))), ISNUMBER(SEARCH("linkedin",LOWER(G23))), ISNUMBER(SEARCH("linktr.ee",LOWER(G23))), ISNUMBER(SEARCH("g.page",LOWER(G23))), ISNUMBER(SEARCH("maps.app.goo.gl",LOWER(G23))), ISNUMBER(SEARCH("goo.gl",LOWER(G23))) ), "Social Media", "Official Website")) -> No Website | L23: =IF(E23>=4.5,"Excellent", IF(E23>=4,"Good", IF(E23>=3,"Average","Poor"))) -> Excellent | M23: =IF(F23>=1000,"1000+ Reviews", IF(F23>=500,"500-999 Reviews", IF(F23>=100,"100-499 Reviews", "Below 100 Reviews"))) -> 500-999 Reviews | N23: =IF(K23="Official Website","Low Opportunity", IF(AND(K23="No Website",E23>=4.5,F23>=500),"Very High Opportunity", IF(AND(K23="No Website",E23>=4.5),"High Opportunity", IF(K23="Social Media","Medium Opportunity","Low Opportunity")))) -> Very High Opportunity
A24: Burari, Delhi | B24: cafes | C24: Delhi Foodie Cafe (DFC) | D24: chowk, Burari, Delhi, 110084, India | E24: 4.4 | F24: 57 | H24: 099582 49957 | I24: restaurant, food, point_of_interest, establishment | J24: =IF(COUNTIFS($C$2:C24,C24,$D$2:D24,D24)=1,"Unique","Duplicate") -> Unique | K24: =IF(TRIM(G24)="","No Website", IF(OR( ISNUMBER(SEARCH("facebook",LOWER(G24))), ISNUMBER(SEARCH("instagram",LOWER(G24))), ISNUMBER(SEARCH("wa.me",LOWER(G24))), ISNUMBER(SEARCH("whatsapp",LOWER(G24))), ISNUMBER(SEARCH("youtube",LOWER(G24))), ISNUMBER(SEARCH("twitter",LOWER(G24))), ISNUMBER(SEARCH("x.com",LOWER(G24))), ISNUMBER(SEARCH("linkedin",LOWER(G24))), ISNUMBER(SEARCH("linktr.ee",LOWER(G24))), ISNUMBER(SEARCH("g.page",LOWER(G24))), ISNUMBER(SEARCH("maps.app.goo.gl",LOWER(G24))), ISNUMBER(SEARCH("goo.gl",LOWER(G24))) ), "Social Media", "Official Website")) -> No Website | L24: =IF(E24>=4.5,"Excellent", IF(E24>=4,"Good", IF(E24>=3,"Average","Poor"))) -> Good | M24: =IF(F24>=1000,"1000+ Reviews", IF(F24>=500,"500-999 Reviews", IF(F24>=100,"100-499 Reviews", "Below 100 Reviews"))) -> Below 100 Reviews | N24: =IF(K24="Official Website","Low Opportunity", IF(AND(K24="No Website",E24>=4.5,F24>=500),"Very High Opportunity", IF(AND(K24="No Website",E24>=4.5),"High Opportunity", IF(K24="Social Media","Medium Opportunity","Low Opportunity")))) -> Low Opportunity
A25: Uttam Nagar, Delhi | B25: tutoring centers | C25: Mathematics Specialist- Dwar (@RatanKumarGupta) | D25: A-13, Shish Ram Park, Block C, Uttam Nagar East, Uttam Nagar, New Delhi, Delhi, 110059, India | E25: 5 | F25: 516 | H25: 095555 55136 | I25: point_of_interest, establishment | J25: =IF(COUNTIFS($C$2:C25,C25,$D$2:D25,D25)=1,"Unique","Duplicate") -> Unique | K25: =IF(TRIM(G25)="","No Website", IF(OR( ISNUMBER(SEARCH("facebook",LOWER(G25))), ISNUMBER(SEARCH("instagram",LOWER(G25))), ISNUMBER(SEARCH("wa.me",LOWER(G25))), ISNUMBER(SEARCH("whatsapp",LOWER(G25))), ISNUMBER(SEARCH("youtube",LOWER(G25))), ISNUMBER(SEARCH("twitter",LOWER(G25))), ISNUMBER(SEARCH("x.com",LOWER(G25))), ISNUMBER(SEARCH("linkedin",LOWER(G25))), ISNUMBER(SEARCH("linktr.ee",LOWER(G25))), ISNUMBER(SEARCH("g.page",LOWER(G25))), ISNUMBER(SEARCH("maps.app.goo.gl",LOWER(G25))), ISNUMBER(SEARCH("goo.gl",LOWER(G25))) ), "Social Media", "Official Website")) -> No Website | L25: =IF(E25>=4.5,"Excellent", IF(E25>=4,"Good", IF(E25>=3,"Average","Poor"))) -> Excellent | M25: =IF(F25>=1000,"1000+ Reviews", IF(F25>=500,"500-999 Reviews", IF(F25>=100,"100-499 Reviews", "Below 100 Reviews"))) -> 500-999 Reviews | N25: =IF(K25="Official Website","Low Opportunity", IF(AND(K25="No Website",E25>=4.5,F25>=500),"Very High Opportunity", IF(AND(K25="No Website",E25>=4.5),"High Opportunity", IF(K25="Social Media","Medium Opportunity","Low Opportunity")))) -> Very High Opportunity
A26: Burari, Delhi | B26: cafes | C26: The old smoke cafe | D26: 109, Sant Nagar Marg, Block B, Sant Nagar, Burari, Delhi, 110084, India | E26: 3.4 | F26: 97 | I26: bar, point_of_interest, establishment | J26: =IF(COUNTIFS($C$2:C26,C26,$D$2:D26,D26)=1,"Unique","Duplicate") -> Unique | K26: =IF(TRIM(G26)="","No Website", IF(OR( ISNUMBER(SEARCH("facebook",LOWER(G26))), ISNUMBER(SEARCH("instagram",LOWER(G26))), ISNUMBER(SEARCH("wa.me",LOWER(G26))), ISNUMBER(SEARCH("whatsapp",LOWER(G26))), ISNUMBER(SEARCH("youtube",LOWER(G26))), ISNUMBER(SEARCH("twitter",LOWER(G26))), ISNUMBER(SEARCH("x.com",LOWER(G26))), ISNUMBER(SEARCH("linkedin",LOWER(G26))), ISNUMBER(SEARCH("linktr.ee",LOWER(G26))), ISNUMBER(SEARCH("g.page",LOWER(G26))), ISNUMBER(SEARCH("maps.app.goo.gl",LOWER(G26))), ISNUMBER(SEARCH("goo.gl",LOWER(G26))) ), "Social Media", "Official Website")) -> No Website | L26: =IF(E26>=4.5,"Excellent", IF(E26>=4,"Good", IF(E26>=3,"Average","Poor"))) -> Average | M26: =IF(F26>=1000,"1000+ Reviews", IF(F26>=500,"500-999 Reviews", IF(F26>=100,"100-499 Reviews", "Below 100 Reviews"))) -> Below 100 Reviews | N26: =IF(K26="Official Website","Low Opportunity", IF(AND(K26="No Website",E26>=4.5,F26>=500),"Very High Opportunity", IF(AND(K26="No Website",E26>=4.5),"High Opportunity", IF(K26="Social Media","Medium Opportunity","Low Opportunity")))) -> Low Opportunity
A27: Burari, Delhi | B27: cafes | C27: The Delicious Cafe | D27: 1st floor, CHARAN SINGH PLAZA, Main 100, Futa Road, opposite kapil Public school, near Shalimar Palace, Conductor Colony, Burari Garhi, Burari, Delhi, 110084, India | E27: 4.4 | F27: 39 | G27: https://thedeliciouscafe.landinghero.app/ | H27: 088511 59031 | I27: restaurant, cafe, food, point_of_interest, establishment | J27: =IF(COUNTIFS($C$2:C27,C27,$D$2:D27,D27)=1,"Unique","Duplicate") -> Unique | K27: =IF(TRIM(G27)="","No Website", IF(OR( ISNUMBER(SEARCH("facebook",LOWER(G27))), ISNUMBER(SEARCH("instagram",LOWER(G27))), ISNUMBER(SEARCH("wa.me",LOWER(G27))), ISNUMBER(SEARCH("whatsapp",LOWER(G27))), ISNUMBER(SEARCH("youtube",LOWER(G27))), ISNUMBER(SEARCH("twitter",LOWER(G27))), ISNUMBER(SEARCH("x.com",LOWER(G27))), ISNUMBER(SEARCH("linkedin",LOWER(G27))), ISNUMBER(SEARCH("linktr.ee",LOWER(G27))), ISNUMBER(SEARCH("g.page",LOWER(G27))), ISNUMBER(SEARCH("maps.app.goo.gl",LOWER(G27))), ISNUMBER(SEARCH("goo.gl",LOWER(G27))) ), "Social Media", "Official Website")) -> Official Website | L27: =IF(E27>=4.5,"Excellent", IF(E27>=4,"Good", IF(E27>=3,"Average","Poor"))) -> Good | M27: =IF(F27>=1000,"1000+ Reviews", IF(F27>=500,"500-999 Reviews", IF(F27>=100,"100-499 Reviews", "Below 100 Reviews"))) -> Below 100 Reviews | N27: =IF(K27="Official Website","Low Opportunity", IF(AND(K27="No Website",E27>=4.5,F27>=500),"Very High Opportunity", IF(AND(K27="No Website",E27>=4.5),"High Opportunity", IF(K27="Social Media","Medium Opportunity","Low Opportunity")))) -> Low Opportunity
A28: Burari, Delhi | B28: cafes | C28: URBAN EATS CAFE | D28: House Number 1 Gali Number 20 Block 8A Swami dayanand Colony, On, Oscar Public School Rd, Block 8A, Kaushik Enclave, Swami Dayanand Enclave, Burari, Delhi, 110084, India | E28: 4.9 | F28: 123 | G28: https://urban-eats-cafe.grexa.site/ | H28: 083768 56474 | I28: food_court, cafe, fast_food_restaurant, chinese_restaurant, restaurant, food, point_of_interest, establishment | J28: =IF(COUNTIFS($C$2:C28,C28,$D$2:D28,D28)=1,"Unique","Duplicate") -> Unique | K28: =IF(TRIM(G28)="","No Website", IF(OR( ISNUMBER(SEARCH("facebook",LOWER(G28))), ISNUMBER(SEARCH("instagram",LOWER(G28))), ISNUMBER(SEARCH("wa.me",LOWER(G28))), ISNUMBER(SEARCH("whatsapp",LOWER(G28))), ISNUMBER(SEARCH("youtube",LOWER(G28))), ISNUMBER(SEARCH("twitter",LOWER(G28))), ISNUMBER(SEARCH("x.com",LOWER(G28))), ISNUMBER(SEARCH("linkedin",LOWER(G28))), ISNUMBER(SEARCH("linktr.ee",LOWER(G28))), ISNUMBER(SEARCH("g.page",LOWER(G28))), ISNUMBER(SEARCH("maps.app.goo.gl",LOWER(G28))), ISNUMBER(SEARCH("goo.gl",LOWER(G28))) ), "Social Media", "Official Website")) -> Official Website | L28: =IF(E28>=4.5,"Excellent", IF(E28>=4,"Good", IF(E28>=3,"Average","Poor"))) -> Excellent | M28: =IF(F28>=1000,"1000+ Reviews", IF(F28>=500,"500-999 Reviews", IF(F28>=100,"100-499 Reviews", "Below 100 Reviews"))) -> 100-499 Reviews | N28: =IF(K28="Official Website","Low Opportunity", IF(AND(K28="No Website",E28>=4.5,F28>=500),"Very High Opportunity", IF(AND(K28="No Website",E28>=4.5),"High Opportunity", IF(K28="Social Media","Medium Opportunity","Low Opportunity")))) -> Low Opportunity
A29: Burari, Delhi | B29: salons | C29: AD BEAUTY LOUNGE LADIES PARLOUR | D29: Gali Number 8, Block B, Sant Nagar, Burari, Delhi, 110084, India | E29: 5 | F29: 506 | H29: 081788 66123 | I29: beauty_salon, point_of_interest, service, establishment | J29: =IF(COUNTIFS($C$2:C29,C29,$D$2:D29,D29)=1,"Unique","Duplicate") -> Unique | K29: =IF(TRIM(G29)="","No Website", IF(OR( ISNUMBER(SEARCH("facebook",LOWER(G29))), ISNUMBER(SEARCH("instagram",LOWER(G29))), ISNUMBER(SEARCH("wa.me",LOWER(G29))), ISNUMBER(SEARCH("whatsapp",LOWER(G29))), ISNUMBER(SEARCH("youtube",LOWER(G29))), ISNUMBER(SEARCH("twitter",LOWER(G29))), ISNUMBER(SEARCH("x.com",LOWER(G29))), ISNUMBER(SEARCH("linkedin",LOWER(G29))), ISNUMBER(SEARCH("linktr.ee",LOWER(G29))), ISNUMBER(SEARCH("g.page",LOWER(G29))), ISNUMBER(SEARCH("maps.app.goo.gl",LOWER(G29))), ISNUMBER(SEARCH("goo.gl",LOWER(G29))) ), "Social Media", "Official Website")) -> No Website | L29: =IF(E29>=4.5,"Excellent", IF(E29>=4,"Good", IF(E29>=3,"Average","Poor"))) -> Excellent | M29: =IF(F29>=1000,"1000+ Reviews", IF(F29>=500,"500-999 Reviews", IF(F29>=100,"100-499 Reviews", "Below 100 Reviews"))) -> 500-999 Reviews | N29: =IF(K29="Official Website","Low Opportunity", IF(AND(K29="No Website",E29>=4.5,F29>=500),"Very High Opportunity", IF(AND(K29="No Website",E29>=4.5),"High Opportunity", IF(K29="Social Media","Medium Opportunity","Low Opportunity")))) -> Very High Opportunity
A30: Mukherjee Nagar, Delhi | B30: tutoring centers | C30: Maths Mantra Best Maths Institute(Maths by Puneet chaudhary) | D30: Shop No-1, building 29/30, jaina complex, dr. Mukherjee nagar_09, near Batra Cinema, Mukherjee Nagar, New Delhi, Delhi, 110033, India | E30: 5 | F30: 499 | H30: 099177 77707 | I30: educational_institution, point_of_interest, establishment | J30: =IF(COUNTIFS($C$2:C30,C30,$D$2:D30,D30)=1,"Unique","Duplicate") -> Unique | K30: =IF(TRIM(G30)="","No Website", IF(OR( ISNUMBER(SEARCH("facebook",LOWER(G30))), ISNUMBER(SEARCH("instagram",LOWER(G30))), ISNUMBER(SEARCH("wa.me",LOWER(G30))), ISNUMBER(SEARCH("whatsapp",LOWER(G30))), ISNUMBER(SEARCH("youtube",LOWER(G30))), ISNUMBER(SEARCH("twitter",LOWER(G30))), ISNUMBER(SEARCH("x.com",LOWER(G30))), ISNUMBER(SEARCH("linkedin",LOWER(G30))), ISNUMBER(SEARCH("linktr.ee",LOWER(G30))), ISNUMBER(SEARCH("g.page",LOWER(G30))), ISNUMBER(SEARCH("maps.app.goo.gl",LOWER(G30))), ISNUMBER(SEARCH("goo.gl",LOWER(G30))) ), "Social Media", "Official Website")) -> No Website | L30: =IF(E30>=4.5,"Excellent", IF(E30>=4,"Good", IF(E30>=3,"Average","Poor"))) -> Excellent | M30: =IF(F30>=1000,"1000+ Reviews", IF(F30>=500,"500-999 Reviews", IF(F30>=100,"100-499 Reviews", "Below 100 Reviews"))) -> 100-499 Reviews | N30: =IF(K30="Official Website","Low Opportunity", IF(AND(K30="No Website",E30>=4.5,F30>=500),"Very High Opportunity", IF(AND(K30="No Website",E30>=4.5),"High Opportunity", IF(K30="Social Media","Medium Opportunity","Low Opportunity")))) -> High Opportunity
A31: Mukherjee Nagar, Delhi | B31: tutoring centers | C31: Shresth PCS Academy, Best PCS Test Series Coaching in Mukharjee nagar delhi | D31: 2nd floor, Mukherjee Tower, near Satija Building, Mukherjee Nagar, Delhi, 110033, India | E31: 5 | F31: 447 | H31: 093138 83336 | I31: educational_institution, point_of_interest, establishment | J31: =IF(COUNTIFS($C$2:C31,C31,$D$2:D31,D31)=1,"Unique","Duplicate") -> Unique | K31: =IF(TRIM(G31)="","No Website", IF(OR( ISNUMBER(SEARCH("facebook",LOWER(G31))), ISNUMBER(SEARCH("instagram",LOWER(G31))), ISNUMBER(SEARCH("wa.me",LOWER(G31))), ISNUMBER(SEARCH("whatsapp",LOWER(G31))), ISNUMBER(SEARCH("youtube",LOWER(G31))), ISNUMBER(SEARCH("twitter",LOWER(G31))), ISNUMBER(SEARCH("x.com",LOWER(G31))), ISNUMBER(SEARCH("linkedin",LOWER(G31))), ISNUMBER(SEARCH("linktr.ee",LOWER(G31))), ISNUMBER(SEARCH("g.page",LOWER(G31))), ISNUMBER(SEARCH("maps.app.goo.gl",LOWER(G31))), ISNUMBER(SEARCH("goo.gl",LOWER(G31))) ), "Social Media", "Official Website")) -> No Website | L31: =IF(E31>=4.5,"Excellent", IF(E31>=4,"Good", IF(E31>=3,"Average","Poor"))) -> Excellent | M31: =IF(F31>=1000,"1000+ Reviews", IF(F31>=500,"500-999 Reviews", IF(F31>=100,"100-499 Reviews", "Below 100 Reviews"))) -> 100-499 Reviews | N31: =IF(K31="Official Website","Low Opportunity", IF(AND(K31="No Website",E31>=4.5,F31>=500),"Very High Opportunity", IF(AND(K31="No Website",E31>=4.5),"High Opportunity", IF(K31="Social Media","Medium Opportunity","Low Opportunity")))) -> High Opportunity
A32: Preet Vihar, Delhi | B32: electronics shops | C32: SHREE BALAJI ELECTRONICS | D32: Chauhan Tower, A-25, Vihar Road, Madhu Vihar, I.P.Extension, Patparganj, New Delhi, Delhi, 110092, India | E32: 5 | F32: 423 | H32: 096676 32924 | I32: wholesaler, point_of_interest, establishment | J32: =IF(COUNTIFS($C$2:C32,C32,$D$2:D32,D32)=1,"Unique","Duplicate") -> Unique | K32: =IF(TRIM(G32)="","No Website", IF(OR( ISNUMBER(SEARCH("facebook",LOWER(G32))), ISNUMBER(SEARCH("instagram",LOWER(G32))), ISNUMBER(SEARCH("wa.me",LOWER(G32))), ISNUMBER(SEARCH("whatsapp",LOWER(G32))), ISNUMBER(SEARCH("youtube",LOWER(G32))), ISNUMBER(SEARCH("twitter",LOWER(G32))), ISNUMBER(SEARCH("x.com",LOWER(G32))), ISNUMBER(SEARCH("linkedin",LOWER(G32))), ISNUMBER(SEARCH("linktr.ee",LOWER(G32))), ISNUMBER(SEARCH("g.page",LOWER(G32))), ISNUMBER(SEARCH("maps.app.goo.gl",LOWER(G32))), ISNUMBER(SEARCH("goo.gl",LOWER(G32))) ), "Social Media", "Official Website")) -> No Website | L32: =IF(E32>=4.5,"Excellent", IF(E32>=4,"Good", IF(E32>=3,"Average","Poor"))) -> Excellent | M32: =IF(F32>=1000,"1000+ Reviews", IF(F32>=500,"500-999 Reviews", IF(F32>=100,"100-499 Reviews", "Below 100 Reviews"))) -> 100-499 Reviews | N32: =IF(K32="Official Website","Low Opportunity", IF(AND(K32="No Website",E32>=4.5,F32>=500),"Very High Opportunity", IF(AND(K32="No Website",E32>=4.5),"High Opportunity", IF(K32="Social Media","Medium Opportunity","Low Opportunity")))) -> High Opportunity
A33: Connaught Place, New Delhi | B33: mobile shops | C33: Hotspot Mobile Store | D33: No E21, Ground Floor, Maharaja Agrasen Marg, Block E, Kamla Nagar, New Delhi, Delhi, 110007, India | E33: 5 | F33: 417 | H33: 070423 43404 | I33: cell_phone_store, store, point_of_interest, establishment | J33: =IF(COUNTIFS($C$2:C33,C33,$D$2:D33,D33)=1,"Unique","Duplicate") -> Unique | K33: =IF(TRIM(G33)="","No Website", IF(OR( ISNUMBER(SEARCH("facebook",LOWER(G33))), ISNUMBER(SEARCH("instagram",LOWER(G33))), ISNUMBER(SEARCH("wa.me",LOWER(G33))), ISNUMBER(SEARCH("whatsapp",LOWER(G33))), ISNUMBER(SEARCH("youtube",LOWER(G33))), ISNUMBER(SEARCH("twitter",LOWER(G33))), ISNUMBER(SEARCH("x.com",LOWER(G33))), ISNUMBER(SEARCH("linkedin",LOWER(G33))), ISNUMBER(SEARCH("linktr.ee",LOWER(G33))), ISNUMBER(SEARCH("g.page",LOWER(G33))), ISNUMBER(SEARCH("maps.app.goo.gl",LOWER(G33))), ISNUMBER(SEARCH("goo.gl",LOWER(G33))) ), "Social Media", "Official Website")) -> No Website | L33: =IF(E33>=4.5,"Excellent", IF(E33>=4,"Good", IF(E33>=3,"Average","Poor"))) -> Excellent | M33: =IF(F33>=1000,"1000+ Reviews", IF(F33>=500,"500-999 Reviews", IF(F33>=100,"100-499 Reviews", "Below 100 Reviews"))) -> 100-499 Reviews | N33: =IF(K33="Official Website","Low Opportunity", IF(AND(K33="No Website",E33>=4.5,F33>=500),"Very High Opportunity", IF(AND(K33="No Website",E33>=4.5),"High Opportunity", IF(K33="Social Media","Medium Opportunity","Low Opportunity")))) -> High Opportunity
A34: Burari, Delhi | B34: cafes | C34: Le Food Gallery | D34: 701, Main Burari Chowk, near Union Bank, Conductor Colony, Baba Colony, Burari, Delhi, 110084, India | E34: 4.4 | F34: 33 | H34: 099107 23448 | I34: cafe, restaurant, food, point_of_interest, establishment | J34: =IF(COUNTIFS($C$2:C34,C34,$D$2:D34,D34)=1,"Unique","Duplicate") -> Unique | K34: =IF(TRIM(G34)="","No Website", IF(OR( ISNUMBER(SEARCH("facebook",LOWER(G34))), ISNUMBER(SEARCH("instagram",LOWER(G34))), ISNUMBER(SEARCH("wa.me",LOWER(G34))), ISNUMBER(SEARCH("whatsapp",LOWER(G34))), ISNUMBER(SEARCH("youtube",LOWER(G34))), ISNUMBER(SEARCH("twitter",LOWER(G34))), ISNUMBER(SEARCH("x.com",LOWER(G34))), ISNUMBER(SEARCH("linkedin",LOWER(G34))), ISNUMBER(SEARCH("linktr.ee",LOWER(G34))), ISNUMBER(SEARCH("g.page",LOWER(G34))), ISNUMBER(SEARCH("maps.app.goo.gl",LOWER(G34))), ISNUMBER(SEARCH("goo.gl",LOWER(G34))) ), "Social Media", "Official Website")) -> No Website | L34: =IF(E34>=4.5,"Excellent", IF(E34>=4,"Good", IF(E34>=3,"Average","Poor"))) -> Good | M34: =IF(F34>=1000,"1000+ Reviews", IF(F34>=500,"500-999 Reviews", IF(F34>=100,"100-499 Reviews", "Below 100 Reviews"))) -> Below 100 Reviews | N34: =IF(K34="Official Website","Low Opportunity", IF(AND(K34="No Website",E34>=4.5,F34>=500),"Very High Opportunity", IF(AND(K34="No Website",E34>=4.5),"High Opportunity", IF(K34="Social Media","Medium Opportunity","Low Opportunity")))) -> Low Opportunity
A35: Uttam Nagar, Delhi | B35: salons | C35: Oneness Salon & Academy | D35: G-62, School Rd, Vijay Vihar, Block G, Uttam Nagar, Delhi, 110059, India | E35: 5 | F35: 417 | H35: 099582 39925 | I35: beauty_salon, beautician, point_of_interest, service, establishment | J35: =IF(COUNTIFS($C$2:C35,C35,$D$2:D35,D35)=1,"Unique","Duplicate") -> Unique | K35: =IF(TRIM(G35)="","No Website", IF(OR( ISNUMBER(SEARCH("facebook",LOWER(G35))), ISNUMBER(SEARCH("instagram",LOWER(G35))), ISNUMBER(SEARCH("wa.me",LOWER(G35))), ISNUMBER(SEARCH("whatsapp",LOWER(G35))), ISNUMBER(SEARCH("youtube",LOWER(G35))), ISNUMBER(SEARCH("twitter",LOWER(G35))), ISNUMBER(SEARCH("x.com",LOWER(G35))), ISNUMBER(SEARCH("linkedin",LOWER(G35))), ISNUMBER(SEARCH("linktr.ee",LOWER(G35))), ISNUMBER(SEARCH("g.page",LOWER(G35))), ISNUMBER(SEARCH("maps.app.goo.gl",LOWER(G35))), ISNUMBER(SEARCH("goo.gl",LOWER(G35))) ), "Social Media", "Official Website")) -> No Website | L35: =IF(E35>=4.5,"Excellent", IF(E35>=4,"Good", IF(E35>=3,"Average","Poor"))) -> Excellent | M35: =IF(F35>=1000,"1000+ Reviews", IF(F35>=500,"500-999 Reviews", IF(F35>=100,"100-499 Reviews", "Below 100 Reviews"))) -> 100-499 Reviews | N35: =IF(K35="Official Website","Low Opportunity", IF(AND(K35="No Website",E35>=4.5,F35>=500),"Very High Opportunity", IF(AND(K35="No Website",E35>=4.5),"High Opportunity", IF(K35="Social Media","Medium Opportunity","Low Opportunity")))) -> High Opportunity
A36: Shahdara, Delhi | B36: mobile shops | C36: MOBILE ADDICTION - BEST MOBILE SHOP DELHI | D36: C-240, Main 100 Feet Rd, Durgapuri Extension, Hardevpuri, Shahdara, Delhi, 110032, India | E36: 5 | F36: 407 | H36: 087009 19018 | I36: cell_phone_store, store, point_of_interest, establishment | J36: =IF(COUNTIFS($C$2:C36,C36,$D$2:D36,D36)=1,"Unique","Duplicate") -> Unique | K36: =IF(TRIM(G36)="","No Website", IF(OR( ISNUMBER(SEARCH("facebook",LOWER(G36))), ISNUMBER(SEARCH("instagram",LOWER(G36))), ISNUMBER(SEARCH("wa.me",LOWER(G36))), ISNUMBER(SEARCH("whatsapp",LOWER(G36))), ISNUMBER(SEARCH("youtube",LOWER(G36))), ISNUMBER(SEARCH("twitter",LOWER(G36))), ISNUMBER(SEARCH("x.com",LOWER(G36))), ISNUMBER(SEARCH("linkedin",LOWER(G36))), ISNUMBER(SEARCH("linktr.ee",LOWER(G36))), ISNUMBER(SEARCH("g.page",LOWER(G36))), ISNUMBER(SEARCH("maps.app.goo.gl",LOWER(G36))), ISNUMBER(SEARCH("goo.gl",LOWER(G36))) ), "Social Media", "Official Website")) -> No Website | L36: =IF(E36>=4.5,"Excellent", IF(E36>=4,"Good", IF(E36>=3,"Average","Poor"))) -> Excellent | M36: =IF(F36>=1000,"1000+ Reviews", IF(F36>=500,"500-999 Reviews", IF(F36>=100,"100-499 Reviews", "Below 100 Reviews"))) -> 100-499 Reviews | N36: =IF(K36="Official Website","Low Opportunity", IF(AND(K36="No Website",E36>=4.5,F36>=500),"Very High Opportunity", IF(AND(K36="No Website",E36>=4.5),"High Opportunity", IF(K36="Social Media","Medium Opportunity","Low Opportunity")))) -> High Opportunity
A37: Burari, Delhi | B37: salons | C37: Tress Trends Unisex Salon | D37: Main, Burari Rd, opposite Shalimar Banquet Hall, Data Ram Tyagi Enclave, Block A, Extension Colony, Burari, Delhi, 110084, India | E37: 4.7 | F37: 562 | G37: https://tress-trends-salon.respark.in/tress-trends-salon-240/burari | H37: 093550 55561 | I37: makeup_artist, hair_salon, hair_care, nail_salon, beauty_salon, point_of_interest, service, establishment | J37: =IF(COUNTIFS($C$2:C37,C37,$D$2:D37,D37)=1,"Unique","Duplicate") -> Unique | K37: =IF(TRIM(G37)="","No Website", IF(OR( ISNUMBER(SEARCH("facebook",LOWER(G37))), ISNUMBER(SEARCH("instagram",LOWER(G37))), ISNUMBER(SEARCH("wa.me",LOWER(G37))), ISNUMBER(SEARCH("whatsapp",LOWER(G37))), ISNUMBER(SEARCH("youtube",LOWER(G37))), ISNUMBER(SEARCH("twitter",LOWER(G37))), ISNUMBER(SEARCH("x.com",LOWER(G37))), ISNUMBER(SEARCH("linkedin",LOWER(G37))), ISNUMBER(SEARCH("linktr.ee",LOWER(G37))), ISNUMBER(SEARCH("g.page",LOWER(G37))), ISNUMBER(SEARCH("maps.app.goo.gl",LOWER(G37))), ISNUMBER(SEARCH("goo.gl",LOWER(G37))) ), "Social Media", "Official Website")) -> Official Website | L37: =IF(E37>=4.5,"Excellent", IF(E37>=4,"Good", IF(E37>=3,"Average","Poor"))) -> Excellent | M37: =IF(F37>=1000,"1000+ Reviews", IF(F37>=500,"500-999 Reviews", IF(F37>=100,"100-499 Reviews", "Below 100 Reviews"))) -> 500-999 Reviews | N37: =IF(K37="Official Website","Low Opportunity", IF(AND(K37="No Website",E37>=4.5,F37>=500),"Very High Opportunity", IF(AND(K37="No Website",E37>=4.5),"High Opportunity", IF(K37="Social Media","Medium Opportunity","Low Opportunity")))) -> Low Opportunity
A38: Rohini, Delhi | B38: gyms | C38: Swag Fit Gym and Studio | D38: S-38, CSC -13,BLOCK D-3 DDA Market Rohini Sec-16 near Motherdairy booth 510, D, 3, DDA Market, Pocket 2, Sector 16, Rohini, Delhi, 110089, India | E38: 5 | F38: 368 | H38: 098184 87484 | I38: fitness_center, gym, sports_activity_location, health, point_of_interest, establishment | J38: =IF(COUNTIFS($C$2:C38,C38,$D$2:D38,D38)=1,"Unique","Duplicate") -> Unique | K38: =IF(TRIM(G38)="","No Website", IF(OR( ISNUMBER(SEARCH("facebook",LOWER(G38))), ISNUMBER(SEARCH("instagram",LOWER(G38))), ISNUMBER(SEARCH("wa.me",LOWER(G38))), ISNUMBER(SEARCH("whatsapp",LOWER(G38))), ISNUMBER(SEARCH("youtube",LOWER(G38))), ISNUMBER(SEARCH("twitter",LOWER(G38))), ISNUMBER(SEARCH("x.com",LOWER(G38))), ISNUMBER(SEARCH("linkedin",LOWER(G38))), ISNUMBER(SEARCH("linktr.ee",LOWER(G38))), ISNUMBER(SEARCH("g.page",LOWER(G38))), ISNUMBER(SEARCH("maps.app.goo.gl",LOWER(G38))), ISNUMBER(SEARCH("goo.gl",LOWER(G38))) ), "Social Media", "Official Website")) -> No Website | L38: =IF(E38>=4.5,"Excellent", IF(E38>=4,"Good", IF(E38>=3,"Average","Poor"))) -> Excellent | M38: =IF(F38>=1000,"1000+ Reviews", IF(F38>=500,"500-999 Reviews", IF(F38>=100,"100-499 Reviews", "Below 100 Reviews"))) -> 100-499 Reviews | N38: =IF(K38="Official Website","Low Opportunity", IF(AND(K38="No Website",E38>=4.5,F38>=500),"Very High Opportunity", IF(AND(K38="No Website",E38>=4.5),"High Opportunity", IF(K38="Social Media","Medium Opportunity","Low Opportunity")))) -> High Opportunity
A39: Burari, Delhi | B39: salons | C39: The Valid Unisex Salon - Best Makeup Artist in Delhi, Bridal Makeup Artist, Nail Extension & Beauty Parlour in Burari, Delhi | D39: Plot No Pvt- 4 Khasra No- 122, Ground Floor Extanded, 5/1, Laldora, Sant Nagar, Burari, Delhi, 110084, India | E39: 4.5 | F39: 91 | G39: https://thevalidunisexsalon.com/ | H39: 092056 56721 | I39: beauty_salon, makeup_artist, beautician, massage_spa, massage, spa, hair_salon, hair_care, nail_salon, store, point_of_interest, service, establishment | J39: =IF(COUNTIFS($C$2:C39,C39,$D$2:D39,D39)=1,"Unique","Duplicate") -> Unique | K39: =IF(TRIM(G39)="","No Website", IF(OR( ISNUMBER(SEARCH("facebook",LOWER(G39))), ISNUMBER(SEARCH("instagram",LOWER(G39))), ISNUMBER(SEARCH("wa.me",LOWER(G39))), ISNUMBER(SEARCH("whatsapp",LOWER(G39))), ISNUMBER(SEARCH("youtube",LOWER(G39))), ISNUMBER(SEARCH("twitter",LOWER(G39))), ISNUMBER(SEARCH("x.com",LOWER(G39))), ISNUMBER(SEARCH("linkedin",LOWER(G39))), ISNUMBER(SEARCH("linktr.ee",LOWER(G39))), ISNUMBER(SEARCH("g.page",LOWER(G39))), ISNUMBER(SEARCH("maps.app.goo.gl",LOWER(G39))), ISNUMBER(SEARCH("goo.gl",LOWER(G39))) ), "Social Media", "Official Website")) -> Official Website | L39: =IF(E39>=4.5,"Excellent", IF(E39>=4,"Good", IF(E39>=3,"Average","Poor"))) -> Excellent | M39: =IF(F39>=1000,"1000+ Reviews", IF(F39>=500,"500-999 Reviews", IF(F39>=100,"100-499 Reviews", "Below 100 Reviews"))) -> Below 100 Reviews | N39: =IF(K39="Official Website","Low Opportunity", IF(AND(K39="No Website",E39>=4.5,F39>=500),"Very High Opportunity", IF(AND(K39="No Website",E39>=4.5),"High Opportunity", IF(K39="Social Media","Medium Opportunity","Low Opportunity")))) -> Low Opportunity
A40: Burari, Delhi | B40: salons | C40: Swanky unisex salon | D40: 775, Vijay Colony, Block B, Sant Nagar, Burari, Delhi, 110084, India | E40: 4.4 | F40: 188 | H40: 093101 06196 | I40: beauty_salon, point_of_interest, service, establishment | J40: =IF(COUNTIFS($C$2:C40,C40,$D$2:D40,D40)=1,"Unique","Duplicate") -> Unique | K40: =IF(TRIM(G40)="","No Website", IF(OR( ISNUMBER(SEARCH("facebook",LOWER(G40))), ISNUMBER(SEARCH("instagram",LOWER(G40))), ISNUMBER(SEARCH("wa.me",LOWER(G40))), ISNUMBER(SEARCH("whatsapp",LOWER(G40))), ISNUMBER(SEARCH("youtube",LOWER(G40))), ISNUMBER(SEARCH("twitter",LOWER(G40))), ISNUMBER(SEARCH("x.com",LOWER(G40))), ISNUMBER(SEARCH("linkedin",LOWER(G40))), ISNUMBER(SEARCH("linktr.ee",LOWER(G40))), ISNUMBER(SEARCH("g.page",LOWER(G40))), ISNUMBER(SEARCH("maps.app.goo.gl",LOWER(G40))), ISNUMBER(SEARCH("goo.gl",LOWER(G40))) ), "Social Media", "Official Website")) -> No Website | L40: =IF(E40>=4.5,"Excellent", IF(E40>=4,"Good", IF(E40>=3,"Average","Poor"))) -> Good | M40: =IF(F40>=1000,"1000+ Reviews", IF(F40>=500,"500-999 Reviews", IF(F40>=100,"100-499 Reviews", "Below 100 Reviews"))) -> 100-499 Reviews | N40: =IF(K40="Official Website","Low Opportunity", IF(AND(K40="No Website",E40>=4.5,F40>=500),"Very High Opportunity", IF(AND(K40="No Website",E40>=4.5),"High Opportunity", IF(K40="Social Media","Medium Opportunity","Low Opportunity")))) -> Low Opportunity
...

Sheet Business_Summary
A1: Business Summary Delhi Businesses Digital Presence Analysis
A3: Dataset Overview:
A4: Metric | D4: Value
A5: Total Businesses | D5: =COUNTA(delhi_business_cleaned!C2:C1000)-1 -> 10041
A6: Average Rating | D6: =ROUND(AVERAGE(delhi_business_cleaned!E2:E1000),2) -> 4.52
A7: Average Review Count per Business | D7: =ROUND(AVERAGE(delhi_business_cleaned!F2:F1000),0) -> 681
A9: Digital Presence:
A10: Category | D10: Count | F10: Percentage
A11: Official Website | D11: =COUNTIF(delhi_business_cleaned!K2:K1000,"Official Website") -> 4434 | F11: =D11/D5 -> 0.44158948
A12: Social Media | D12: =COUNTIF(delhi_business_cleaned!K2:K1000,"Social Media") -> 525 | F12: =D12/D5 -> 0.052285629
A13: No Website | D13: =COUNTIF(delhi_business_cleaned!K2:K1000,"No Website") -> 5082 | F13: =D13/D5 -> 0.50612489
A15: Opportunity Summary:
A16: Opportunity Level | D16: Business Count
A17: Very High | D17: =COUNTIF(delhi_business_cleaned!N:N,"Very High Opportunity") -> 183
A18: High | D18: =COUNTIF(delhi_business_cleaned!N:N,"High Opportunity") -> 2671
A19: Medium | D19: =COUNTIF(delhi_business_cleaned!N:N,"Medium Opportunity") -> 525
A20: Low | D20: =COUNTIF(delhi_business_cleaned!N:N,"Low Opportunity") -> 6662
A22: Key Observations:
A23: 1. Approximately 50.6% of businesses do not have an official website, indicating significant opportunities for digital transformation.
A24: 2. Only 44.2% of businesses maintain an official website, while the remaining businesses depend on social media or have no online presence.
A25: 3. Businesses classified as High and Very High Opportunity should be prioritized for website development due to their strong customer ratings.
A26: 4. Customer ratings remain consistently high across the dataset, suggesting many businesses have established reputations despite lacking dedicated websites.
A28: Conclusion:
